<?xml version="1.0" encoding="utf-8"?>
<!-- This URDF was automatically created by SolidWorks to URDF Exporter! Originally created by Stephen Brawner (brawner@gmail.com) 
     Commit Version: 1.6.0-4-g7f85cfe  Build Version: 1.6.7995.38578
     For more information, please see http://wiki.ros.org/sw_urdf_exporter -->
<robot
  name="JQG12">
  <link
    name="base_link">
    <inertial>
      <origin
        xyz="0.0020101 7.5115E-08 0.015227"
        rpy="0 0 0" />
      <mass
        value="0.48823" />
      <inertia
        ixx="0.00046785"
        ixy="7.6454E-10"
        ixz="3.6155E-08"
        iyy="0.00085431"
        iyz="2.8697E-10"
        izz="0.0011457" />
    </inertial>
    <visual>
      <origin
        xyz="0 0 0"
        rpy="0 0 0" />
      <geometry>
        <mesh
          filename="package://JQG12/meshes/base_link.STL" />
      </geometry>
      <material
        name="">
        <color
          rgba="0.75294 0.75294 0.75294 1" />
      </material>
    </visual>
    <collision>
      <origin
        xyz="0 0 0"
        rpy="0 0 0" />
      <geometry>
        <mesh
          filename="package://JQG12/meshes/base_link.STL" />
      </geometry>
    </collision>
  </link>
  <link
    name="l_f_link">
    <inertial>
      <origin
        xyz="0.029689 0.0062796 6.3546E-05"
        rpy="0 0 0" />
      <mass
        value="0.09703" />
      <inertia
        ixx="3.0876E-05"
        ixy="-7.0161E-08"
        ixz="3.7589E-07"
        iyy="3.4106E-05"
        iyz="1.4117E-08"
        izz="2.3976E-05" />
    </inertial>
    <visual>
      <origin
        xyz="0 0 0"
        rpy="0 0 0" />
      <geometry>
        <mesh
          filename="package://JQG12/meshes/l_f_link.STL" />
      </geometry>
      <material
        name="">
        <color
          rgba="1 1 1 1" />
      </material>
    </visual>
    <collision>
      <origin
        xyz="0 0 0"
        rpy="0 0 0" />
      <geometry>
        <mesh
          filename="package://JQG12/meshes/l_f_link.STL" />
      </geometry>
    </collision>
  </link>
  <joint
    name="l_f_joint"
    type="revolute">
    <origin
      xyz="0.0643 0.0375 0.01495"
      rpy="0 0 0" />
    <parent
      link="base_link" />
    <child
      link="l_f_link" />
    <axis
      xyz="1 0 0" />
    <limit
      lower="-1.57"
      upper="1.57"
      effort="0"
      velocity="0" />
  </joint>
  <link
    name="l_f_1link">
    <inertial>
      <origin
        xyz="-0.037087 6.5093E-06 -0.012413"
        rpy="0 0 0" />
      <mass
        value="0.018878" />
      <inertia
        ixx="1.6778E-06"
        ixy="-1.1017E-07"
        ixz="-3.181E-06"
        iyy="1.1567E-05"
        iyz="-3.6872E-08"
        izz="1.0117E-05" />
    </inertial>
    <visual>
      <origin
        xyz="0 0 0"
        rpy="0 0 0" />
      <geometry>
        <mesh
          filename="package://JQG12/meshes/l_f_1link.STL" />
      </geometry>
      <material
        name="">
        <color
          rgba="0.20392 0.20392 0.20392 1" />
      </material>
    </visual>
    <collision>
      <origin
        xyz="0 0 0"
        rpy="0 0 0" />
      <geometry>
        <mesh
          filename="package://JQG12/meshes/l_f_1link.STL" />
      </geometry>
    </collision>
  </link>
  <joint
    name="l_f_1link"
    type="revolute">
    <origin
      xyz="0.02055 0.0323 -0.01"
      rpy="0 -1.24 0" />
    <parent
      link="l_f_link" />
    <child
      link="l_f_1link" />
    <axis
      xyz="0 1 0" />
    <limit
      lower="-1.57"
      upper="1.57"
      effort="0"
      velocity="0" />
  </joint>
  <link
    name="l_f_2link">
    <inertial>
      <origin
        xyz="0.025876 0.00021878 -0.045422"
        rpy="0 0 0" />
      <mass
        value="0.019798" />
      <inertia
        ixx="2.1203E-05"
        ixy="1.4753E-07"
        ixz="1.3808E-05"
        iyy="3.0541E-05"
        iyz="-2.4183E-07"
        izz="1.0141E-05" />
    </inertial>
    <visual>
      <origin
        xyz="0 0 0"
        rpy="0 0 0" />
      <geometry>
        <mesh
          filename="package://JQG12/meshes/l_f_2link.STL" />
      </geometry>
      <material
        name="">
        <color
          rgba="0.62745 0.62745 0.62745 1" />
      </material>
    </visual>
    <collision>
      <origin
        xyz="0 0 0"
        rpy="0 0 0" />
      <geometry>
        <mesh
          filename="package://JQG12/meshes/l_f_2link.STL" />
      </geometry>
    </collision>
  </link>
  <joint
    name="l_f_2link"
    type="revolute">
    <origin
      xyz="-0.085347 0 -0.028565"
      rpy="0 1.74 0" />
    <parent
      link="l_f_1link" />
    <child
      link="l_f_2link" />
    <axis
      xyz="0 1 0" />
    <limit
      lower="-3.14"
      upper="0"
      effort="0"
      velocity="0" />
  </joint>
  <link
    name="l_b_link">
    <inertial>
      <origin
        xyz="-0.029142 0.0062906 6.3684E-05"
        rpy="0 0 0" />
      <mass
        value="0.096818" />
      <inertia
        ixx="3.0834E-05"
        ixy="1.3921E-07"
        ixz="3.7439E-07"
        iyy="3.3971E-05"
        iyz="1.4113E-08"
        izz="2.3844E-05" />
    </inertial>
    <visual>
      <origin
        xyz="0 0 0"
        rpy="0 0 0" />
      <geometry>
        <mesh
          filename="package://JQG12/meshes/l_b_link.STL" />
      </geometry>
      <material
        name="">
        <color
          rgba="1 1 1 1" />
      </material>
    </visual>
    <collision>
      <origin
        xyz="0 0 0"
        rpy="0 0 0" />
      <geometry>
        <mesh
          filename="package://JQG12/meshes/l_b_link.STL" />
      </geometry>
    </collision>
  </link>
  <joint
    name="l_b_joint"
    type="revolute">
    <origin
      xyz="-0.0643 0.0375 0.01495"
      rpy="0 0 0" />
    <parent
      link="base_link" />
    <child
      link="l_b_link" />
    <axis
      xyz="1 0 0" />
    <limit
      lower="-1.57"
      upper="1.57"
      effort="0"
      velocity="0" />
  </joint>
  <link
    name="l_b_1link">
    <inertial>
      <origin
        xyz="-0.026879 6.5079E-06 -0.028408"
        rpy="0 0 0" />
      <mass
        value="0.018878" />
      <inertia
        ixx="6.1897E-06"
        ixy="-7.9844E-08"
        ixz="-5.2763E-06"
        iyy="1.1567E-05"
        iyz="-8.4387E-08"
        izz="5.6053E-06" />
    </inertial>
    <visual>
      <origin
        xyz="0 0 0"
        rpy="0 0 0" />
      <geometry>
        <mesh
          filename="package://JQG12/meshes/l_b_1link.STL" />
      </geometry>
      <material
        name="">
        <color
          rgba="0.20392 0.20392 0.20392 1" />
      </material>
    </visual>
    <collision>
      <origin
        xyz="0 0 0"
        rpy="0 0 0" />
      <geometry>
        <mesh
          filename="package://JQG12/meshes/l_b_1link.STL" />
      </geometry>
    </collision>
  </link>
  <joint
    name="l_b_1link"
    type="revolute">
    <origin
      xyz="-0.04045 0.0323 -0.01"
      rpy="0 -0.80 0" />
    <parent
      link="l_b_link" />
    <child
      link="l_b_1link" />
    <axis
      xyz="0 1 0" />
    <limit
      lower="-1.57"
      upper="1.57"
      effort="0"
      velocity="0" />
  </joint>
  <link
    name="l_b_2link">
    <inertial>
      <origin
        xyz="0.037301 0.00021879 -0.036625"
        rpy="0 0 0" />
      <mass
        value="0.019798" />
      <inertia
        ixx="1.312E-05"
        ixy="2.0799E-07"
        ixz="1.4654E-05"
        iyy="3.0541E-05"
        iyz="-1.9232E-07"
        izz="1.8224E-05" />
    </inertial>
    <visual>
      <origin
        xyz="0 0 0"
        rpy="0 0 0" />
      <geometry>
        <mesh
          filename="package://JQG12/meshes/l_b_2link.STL" />
      </geometry>
      <material
        name="">
        <color
          rgba="0.62745 0.62745 0.62745 1" />
      </material>
    </visual>
    <collision>
      <origin
        xyz="0 0 0"
        rpy="0 0 0" />
      <geometry>
        <mesh
          filename="package://JQG12/meshes/l_b_2link.STL" />
      </geometry>
    </collision>
  </link>
  <joint
    name="l_b_2link"
    type="revolute">
    <origin
      xyz="-0.061855 0 -0.065375"
      rpy="0 1.59 0" />
    <parent
      link="l_b_1link" />
    <child
      link="l_b_2link" />
    <axis
      xyz="0 1 0" />
    <limit
      lower="-3.14"
      upper="0"
      effort="0"
      velocity="0" />
  </joint>
  <link
    name="r_f_link">
    <inertial>
      <origin
        xyz="0.029689 -0.0062796 6.3542E-05"
        rpy="0 0 0" />
      <mass
        value="0.09703" />
      <inertia
        ixx="3.0876E-05"
        ixy="7.0161E-08"
        ixz="3.7576E-07"
        iyy="3.4106E-05"
        iyz="-1.411E-08"
        izz="2.3976E-05" />
    </inertial>
    <visual>
      <origin
        xyz="0 0 0"
        rpy="0 0 0" />
      <geometry>
        <mesh
          filename="package://JQG12/meshes/r_f_link.STL" />
      </geometry>
      <material
        name="">
        <color
          rgba="1 1 1 1" />
      </material>
    </visual>
    <collision>
      <origin
        xyz="0 0 0"
        rpy="0 0 0" />
      <geometry>
        <mesh
          filename="package://JQG12/meshes/r_f_link.STL" />
      </geometry>
    </collision>
  </link>
  <joint
    name="r_f_joint"
    type="revolute">
    <origin
      xyz="0.0643 -0.0375 0.01495"
      rpy="0 0 0" />
    <parent
      link="base_link" />
    <child
      link="r_f_link" />
    <axis
      xyz="1 0 0" />
    <limit
      lower="-1.57"
      upper="1.57"
      effort="0"
      velocity="0" />
  </joint>
  <link
    name="r_f_1link">
    <inertial>
      <origin
        xyz="-0.013037 -9.6442E-06 -0.036954"
        rpy="0 0 0" />
      <mass
        value="0.018883" />
      <inertia
        ixx="1.0042E-05"
        ixy="3.9418E-08"
        ixz="-3.3267E-06"
        iyy="1.1601E-05"
        iyz="1.1173E-07"
        izz="1.7862E-06" />
    </inertial>
    <visual>
      <origin
        xyz="0 0 0"
        rpy="0 0 0" />
      <geometry>
        <mesh
          filename="package://JQG12/meshes/r_f_1link.STL" />
      </geometry>
      <material
        name="">
        <color
          rgba="0.20392 0.20392 0.20392 1" />
      </material>
    </visual>
    <collision>
      <origin
        xyz="0 0 0"
        rpy="0 0 0" />
      <geometry>
        <mesh
          filename="package://JQG12/meshes/r_f_1link.STL" />
      </geometry>
    </collision>
  </link>
  <joint
    name="r_f_1link"
    type="revolute">
    <origin
      xyz="0.02055 -0.0323 -0.01"
      rpy="0 -0.32 0" />
    <parent
      link="r_f_link" />
    <child
      link="r_f_1link" />
    <axis
      xyz="0 -1 0" />
    <limit
      lower="-1.57"
      upper="1.57"
      effort="0"
      velocity="0" />
  </joint>
  <link
    name="r_f_2link">
    <inertial>
      <origin
        xyz="0.032289 -0.00021871 -0.041112"
        rpy="0 0 0" />
      <mass
        value="0.019798" />
      <inertia
        ixx="1.6937E-05"
        ixy="-1.8157E-07"
        ixz="1.4821E-05"
        iyy="3.0541E-05"
        iyz="2.1744E-07"
        izz="1.4407E-05" />
    </inertial>
    <visual>
      <origin
        xyz="0 0 0"
        rpy="0 0 0" />
      <geometry>
        <mesh
          filename="package://JQG12/meshes/r_f_2link.STL" />
      </geometry>
      <material
        name="">
        <color
          rgba="0.62745 0.62745 0.62745 1" />
      </material>
    </visual>
    <collision>
      <origin
        xyz="0 0 0"
        rpy="0 0 0" />
      <geometry>
        <mesh
          filename="package://JQG12/meshes/r_f_2link.STL" />
      </geometry>
    </collision>
  </link>
  <joint
    name="r_f_2link"
    type="revolute">
    <origin
      xyz="-0.029943 0 -0.084873"
      rpy="0 0.97 0" />
    <parent
      link="r_f_1link" />
    <child
      link="r_f_2link" />
    <axis
      xyz="0 -1 0" />
    <limit
      lower="0"
      upper="3.14"
      effort="0"
      velocity="0" />
  </joint>
  <link
    name="r_b_link">
    <inertial>
      <origin
        xyz="-0.029142 -0.0062906 6.3681E-05"
        rpy="0 0 0" />
      <mass
        value="0.096818" />
      <inertia
        ixx="3.0834E-05"
        ixy="-1.3921E-07"
        ixz="3.7428E-07"
        iyy="3.3971E-05"
        iyz="-1.4111E-08"
        izz="2.3844E-05" />
    </inertial>
    <visual>
      <origin
        xyz="0 0 0"
        rpy="0 0 0" />
      <geometry>
        <mesh
          filename="package://JQG12/meshes/r_b_link.STL" />
      </geometry>
      <material
        name="">
        <color
          rgba="1 1 1 1" />
      </material>
    </visual>
    <collision>
      <origin
        xyz="0 0 0"
        rpy="0 0 0" />
      <geometry>
        <mesh
          filename="package://JQG12/meshes/r_b_link.STL" />
      </geometry>
    </collision>
  </link>
  <joint
    name="r_b_joint"
    type="revolute">
    <origin
      xyz="-0.0643 -0.0375 0.01495"
      rpy="0 0 0" />
    <parent
      link="base_link" />
    <child
      link="r_b_link" />
    <axis
      xyz="1 0 0" />
    <limit
      lower="-1.57"
      upper="1.57"
      effort="0"
      velocity="0" />
  </joint>
  <link
    name="r_b_1link">
    <inertial>
      <origin
        xyz="-0.034071 -9.6422E-06 -0.019359"
        rpy="0 0 0" />
      <mass
        value="0.018883" />
      <inertia
        ixx="3.2003E-06"
        ixy="1.0301E-07"
        ixz="-4.5543E-06"
        iyy="1.1601E-05"
        iyz="5.8532E-08"
        izz="8.6279E-06" />
    </inertial>
    <visual>
      <origin
        xyz="0 0 0"
        rpy="0 0 0" />
      <geometry>
        <mesh
          filename="package://JQG12/meshes/r_b_1link.STL" />
      </geometry>
      <material
        name="">
        <color
          rgba="0.20392 0.20392 0.20392 1" />
      </material>
    </visual>
    <collision>
      <origin
        xyz="0 0 0"
        rpy="0 0 0" />
      <geometry>
        <mesh
          filename="package://JQG12/meshes/r_b_1link.STL" />
      </geometry>
    </collision>
  </link>
  <joint
    name="r_b_1link"
    type="revolute">
    <origin
      xyz="-0.04045 -0.0323 -0.01"
      rpy="0 -1.09 0" />
    <parent
      link="r_b_link" />
    <child
      link="r_b_1link" />
    <axis
      xyz="0 -1 0" />
    <limit
      lower="-1.57"
      upper="1.57"
      effort="0"
      velocity="0" />
  </joint>
  <link
    name="r_b_2link">
    <inertial>
      <origin
        xyz="0.042882 -0.00021873 -0.029898"
        rpy="0 0 0" />
      <mass
        value="0.019798" />
      <inertia
        ixx="8.4467E-06"
        ixy="-2.3714E-07"
        ixz="1.3002E-05"
        iyy="3.0541E-05"
        iyz="1.5498E-07"
        izz="2.2897E-05" />
    </inertial>
    <visual>
      <origin
        xyz="0 0 0"
        rpy="0 0 0" />
      <geometry>
        <mesh
          filename="package://JQG12/meshes/r_b_2link.STL" />
      </geometry>
      <material
        name="">
        <color
          rgba="0.62745 0.62745 0.62745 1" />
      </material>
    </visual>
    <collision>
      <origin
        xyz="0 0 0"
        rpy="0 0 0" />
      <geometry>
        <mesh
          filename="package://JQG12/meshes/r_b_2link.STL" />
      </geometry>
    </collision>
  </link>
  <joint
    name="r_b_2link"
    type="revolute">
    <origin
      xyz="-0.078251 0 -0.044462"
      rpy="0 2.02 0" />
    <parent
      link="r_b_1link" />
    <child
      link="r_b_2link" />
    <axis
      xyz="0 -1 0" />
    <limit
      lower="0"
      upper="3.14"
      effort="0"
      velocity="0" />
  </joint>

 
</robot>